<?xml version="1.0" encoding="utf-8"?>
<!-- =================================================================================== -->
<!-- |    This document was autogenerated by xacro from meca_500_r3.urdf.xacro         | -->
<!-- |    EDITING THIS FILE BY HAND IS NOT RECOMMENDED                                 | -->
<!-- =================================================================================== -->
<robot name="meca_500_r3">
  <!-- Base link is the center of the robot's bottom plate -->
  <link name="meca_base_link">
    <visual>
      <origin rpy="0 0 0" xyz="0 0 0"/>
      <geometry>
        <mesh filename="../../meshes/meca_500_r3_base.dae"/>
      </geometry>
    </visual>
    <collision>
      <origin rpy="0 0 0" xyz="0 0 0"/>
      <geometry>
        <mesh filename="../../meshes/meca_500_r3_base_collision.stl"/>
      </geometry>
    </collision>
    <inertial>
  <mass value="3.0"/>
  <origin xyz="0 0 0" rpy="0 0 0"/>
  <inertia ixx="0.004" iyy="0.004" izz="0.004"
               ixy="0" ixz="0" iyz="0"/>
</inertial>
  </link>
  <!-- Joint 1 -->
  <link name="meca_axis_1_link">
    <visual>
      <origin rpy="0 0 0" xyz="0 0 0"/>
      <geometry>
        <mesh filename="../../meshes/meca_500_r3_j1.dae"/>
      </geometry>
    </visual>
    <collision>
      <origin rpy="0 0 0" xyz="0 0 0"/>
      <geometry>
        <mesh filename="../../meshes/meca_500_r3_j1_collision.stl"/>
      </geometry>
    </collision>
    <inertial>
  <mass value="1.2"/>
  <origin xyz="0 0 0" rpy="0 0 0"/>
  <inertia ixx="0.002" iyy="0.002" izz="0.0015"
               ixy="0" ixz="0" iyz="0"/>
</inertial>
  </link>
  <joint name="meca_axis_1_joint" type="revolute">
    <origin rpy="0 0 0" xyz="0.012498 0 0.091"/>
    <parent link="meca_base_link"/>
    <child link="meca_axis_1_link"/>
    <axis xyz="0 0 1"/>
    <limit effort="10.0" lower="-3.05433" upper="3.05433" velocity="2.61799"/>
  </joint>
  <!-- Joint 2 -->
  <link name="meca_axis_2_link">
    <visual>
      <origin rpy="0 0 0" xyz="0 0 0"/>
      <geometry>
        <mesh filename="../../meshes/meca_500_r3_j2.dae"/>
      </geometry>
    </visual>
    <collision>
      <origin rpy="0 0 0" xyz="0 0 0"/>
      <geometry>
        <mesh filename="../../meshes/meca_500_r3_j2_collision.stl"/>
      </geometry>
    </collision>
    <inertial>
  <mass value="1.0"/>
  <origin xyz="0 0 0" rpy="0 0 0"/>
  <inertia ixx="0.0015" iyy="0.0015" izz="0.001"
               ixy="0" ixz="0" iyz="0"/>
</inertial>
  </link>
  <joint name="meca_axis_2_joint" type="revolute">
    <origin rpy="0 0 0" xyz="0 0 0.044"/>
    <parent link="meca_axis_1_link"/>
    <child link="meca_axis_2_link"/>
    <axis xyz="0 1 0"/>
    <limit effort="10.0" lower="-1.22173048" upper="1.5708" velocity="2.61799"/>
  </joint>
  <!-- Joint 3 -->
  <link name="meca_axis_3_link">
    <visual>
      <origin rpy="0 0 0" xyz="0 0 0"/>
      <geometry>
        <mesh filename="../../meshes/meca_500_r3_j3.dae"/>
      </geometry>
    </visual>
    <collision>
      <origin rpy="0 0 0" xyz="0 0 0"/>
      <geometry>
        <mesh filename="../../meshes/meca_500_r3_j3_collision.stl"/>
      </geometry>
    </collision>
    <inertial>
  <mass value="0.8"/>
  <origin xyz="0 0 0" rpy="0 0 0"/>
  <inertia ixx="0.001" ixy="0.0" ixz="0.0"
           iyy="0.001" iyz="0.0"
           izz="0.0008"/>
</inertial>
  </link>
  <joint name="meca_axis_3_joint" type="revolute">
    <origin rpy="0 0 0" xyz="0 0 0.135"/>
    <parent link="meca_axis_2_link"/>
    <child link="meca_axis_3_link"/>
    <axis xyz="0 1 0"/>
    <limit effort="10.0" lower="-2.35619" upper="1.22173048" velocity="3.14159"/>
  </joint>
  <!-- Joint 4 -->
  <link name="meca_axis_4_link">
    <visual>
      <origin rpy="0 0 0" xyz="0 0 0"/>
      <geometry>
        <mesh filename="../../meshes/meca_500_r3_j4.dae"/>
      </geometry>
    </visual>
    <collision>
      <origin rpy="0 0 0" xyz="0 0 0"/>
      <geometry>
        <mesh filename="../../meshes/meca_500_r3_j4_collision.stl"/>
      </geometry>
    </collision>
    <inertial>
  <mass value="0.6"/>
  <origin xyz="0 0 0" rpy="0 0 0"/>
  <inertia ixx="0.0006" ixy="0.0" ixz="0.0"
           iyy="0.0006" iyz="0.0"
           izz="0.0005"/>
</inertial>
  </link>
  <joint name="meca_axis_4_joint" type="revolute">
    <origin rpy="0 0 0" xyz="0 0 0.038"/>
    <parent link="meca_axis_3_link"/>
    <child link="meca_axis_4_link"/>
    <axis xyz="1 0 0"/>
    <limit effort="10.0" lower="-2.96706" upper="2.96706" velocity="5.23599"/>
  </joint>
  <!-- Joint 5 -->
  <link name="meca_axis_5_link">
    <visual>
      <origin rpy="0 0 0" xyz="0 0 0"/>
      <geometry>
        <mesh filename="../../meshes/meca_500_r3_j5.dae"/>
      </geometry>
    </visual>
    <collision>
      <origin rpy="0 0 0" xyz="0 0 0"/>
      <geometry>
        <mesh filename="../../meshes/meca_500_r3_j5_collision.stl"/>
      </geometry>
    </collision>
    <inertial>
  <mass value="0.5"/>
  <origin xyz="0 0 0" rpy="0 0 0"/>
  <inertia ixx="0.0005" ixy="0.0" ixz="0.0"
           iyy="0.0005" iyz="0.0"
           izz="0.0004"/>
</inertial>
  </link>
  <joint name="meca_axis_5_joint" type="revolute">
    <origin rpy="0 0 0" xyz="0.12 0 0"/>
    <parent link="meca_axis_4_link"/>
    <child link="meca_axis_5_link"/>
    <axis xyz="0 1 0"/>
    <limit effort="10.0" lower="-2.00713" upper="2.00713" velocity="5.23599"/>
  </joint>
  <!-- Joint 6 -->
  <link name="meca_axis_6_link">
    <visual>
      <origin rpy="0 0 0" xyz="0 0 0"/>
      <geometry>
        <mesh filename="../../meshes/meca_500_r3_j6.dae"/>
      </geometry>
    </visual>
    <collision>
      <origin rpy="0 0 0" xyz="0 0 0"/>
      <geometry>
        <mesh filename="../../meshes/meca_500_r3_j6_collision.stl"/>
      </geometry>
    </collision>
    <inertial>
  <mass value="0.3"/>
  <origin xyz="0 0 0" rpy="0 0 0"/>
  <inertia ixx="0.0003" ixy="0.0" ixz="0.0"
           iyy="0.0003" iyz="0.0"
           izz="0.00025"/>
</inertial>
  </link>
  <joint name="meca_axis_6_joint" type="revolute">
    <origin rpy="0 0 0" xyz="0.07 0 0"/>
    <parent link="meca_axis_5_link"/>
    <child link="meca_axis_6_link"/>
    <axis xyz="1 0 0"/>
    <limit effort="10.0" lower="-3.14159" upper="3.14159" velocity="8.72665"/>
  </joint>

  <gazebo>
      <plugin
        filename="gz-sim-joint-state-publisher-system"
        name="gz::sim::systems::JointStatePublisher">
        <joint_name>meca_axis_1_joint</joint_name>
        <joint_name>meca_axis_2_joint</joint_name>
        <joint_name>meca_axis_3_joint</joint_name>
        <joint_name>meca_axis_4_joint</joint_name>
        <joint_name>meca_axis_5_joint</joint_name>
        <joint_name>meca_axis_6_joint</joint_name>
      </plugin>
  </gazebo>

  <gazebo>
    <plugin
     filename="gz-sim-joint-controller-system"
     name="gz::sim::systems::JointController">
     <joint_name>meca_axis_1_joint</joint_name>
     <initial_velocity>1.0</initial_velocity>
    </plugin>
  </gazebo>
  <gazebo>
    <plugin
     filename="gz-sim-joint-controller-system"
     name="gz::sim::systems::JointController">
     <joint_name>meca_axis_1_joint</joint_name>
     <initial_velocity>0.0</initial_velocity>
    </plugin>
  </gazebo>
  <gazebo>
    <plugin
     filename="gz-sim-joint-controller-system"
     name="gz::sim::systems::JointController">
     <joint_name>meca_axis_2_joint</joint_name>
     <initial_velocity>0.0</initial_velocity>
    </plugin>
  </gazebo>
  <gazebo>
    <plugin
     filename="gz-sim-joint-controller-system"
     name="gz::sim::systems::JointController">
     <joint_name>meca_axis_3_joint</joint_name>
     <initial_velocity>0.0</initial_velocity>
    </plugin>
  </gazebo>
  <gazebo>
    <plugin
     filename="gz-sim-joint-controller-system"
     name="gz::sim::systems::JointController">
     <joint_name>meca_axis_4_joint</joint_name>
     <initial_velocity>0.0</initial_velocity>
    </plugin>
  </gazebo>
  <gazebo>
    <plugin
     filename="gz-sim-joint-controller-system"
     name="gz::sim::systems::JointController">
     <joint_name>meca_axis_5_joint</joint_name>
     <initial_velocity>0.0</initial_velocity>
    </plugin>
  </gazebo>
  <gazebo>
    <plugin
     filename="gz-sim-joint-controller-system"
     name="gz::sim::systems::JointController">
     <joint_name>meca_axis_6_joint</joint_name>
     <initial_velocity>0.0</initial_velocity>
    </plugin>
  </gazebo>

  <link name="camera_link">
  <visual>
    <origin xyz="0 0 0" rpy="0 0 0"/>
    <geometry>
      <mesh filename="../../meshes/kinect.dae"/> <!-- modello 3D della Kinect -->
      <!-- puoi scalare se necessario -->
      <scale>0.001 0.001 0.001</scale> 
    </geometry>
  </visual>
  <collision>
    <origin xyz="0 0 0" rpy="0 0 0"/>
    <geometry>
      <mesh filename="../../meshes/kinect.dae"/> <!-- collisione semplificata -->
      <scale>0.001 0.001 0.001</scale>
    </geometry>
  </collision>
  <inertial>
    <mass value="0.5"/> <!-- peso realistico della camera -->
    <origin xyz="0 0 0" rpy="0 0 0"/>
    <inertia ixx="0.0005" iyy="0.0005" izz="0.0005" ixy="0" ixz="0" iyz="0"/>
  </inertial>
</link>

<joint name="camera_joint" type="fixed">
  <parent link="meca_axis_6_link"/>
  <child link="camera_link"/>
  <origin xyz="0 0 0.1" rpy="0 0 0"/> <!-- sposta la telecamera sopra il polso -->
</joint>


  <gazebo reference="camera_link">
  <sensor name="rgbd_camera" type="rgbd_camera">
    <update_rate>30.0</update_rate>
    <topic>rgbd_camera</topic>
    <camera>
      <horizontal_fov>0.995</horizontal_fov>
      <image>
        <width>640</width>
        <height>480</height>
        <format>R8G8B8</format>
      </image>
      <clip>
        <near>0.8</near>
        <far>6.0</far>
      </clip>
    </camera>
  </sensor>
  <static>false</static> <!-- deve muoversi con il robot -->
</gazebo>
</robot>